<?xml version="1.0" encoding="utf-8"?>
<!-- This URDF was automatically created by SolidWorks to URDF Exporter! Originally created by Stephen Brawner (brawner@gmail.com) 
     Commit Version: 1.6.0-4-g7f85cfe  Build Version: 1.6.7995.38578
     For more information, please see http://wiki.ros.org/sw_urdf_exporter -->
<robot
  name="robot_arm">
  
  <link name="world"/>
  
  <joint name="world_joint" type="fixed">
    <parent link="world"/>
    <child link="base_link"/>
    <origin xyz="0 0 0" rpy="0 0 0"/>
  </joint>
  
  <link
    name="base_link">
    <inertial>
      <origin
        xyz="0.000117196159259592 7.68725232080936E-09 0.0163035726629275"
        rpy="0 0 0" />
      <mass
        value="0.0960374647687132" />
      <inertia
        ixx="0.000127992374265441"
        ixy="6.84507669967454E-11"
        ixz="3.91396755618814E-06"
        iyy="0.000137660900428952"
        iyz="4.47337777707664E-12"
        izz="0.000207983638444363" />
    </inertial>
    <visual>
      <origin
        xyz="0 0 0"
        rpy="0 0 0" />
      <geometry>
        <mesh
          filename="package://robot_arm_description/meshes/base_link.STL" />
      </geometry>
      <material
        name="">
        <color
          rgba="0.792156862745098 0.819607843137255 0.933333333333333 1" />
      </material>
    </visual>
    <collision>
      <origin
        xyz="0 0 0"
        rpy="0 0 0" />
      <geometry>
        <mesh
          filename="package://robot_arm_description/meshes/base_link.STL" />
      </geometry>
    </collision>
  </link>
  <link
    name="link_1">
    <inertial>
      <origin
        xyz="-0.00414864263261154 0.00510638589359674 0.0172893971363357"
        rpy="0 0 0" />
      <mass
        value="0.0680382266926049" />
      <inertia
        ixx="5.3594660634226E-05"
        ixy="-6.27203699334427E-06"
        ixz="1.13231646661721E-07"
        iyy="4.95562409415516E-05"
        iyz="-8.10968730920396E-06"
        izz="5.467636163819E-05" />
    </inertial>
    <visual>
      <origin
        xyz="0 0 0"
        rpy="0 0 0" />
      <geometry>
        <mesh
          filename="package://robot_arm_description/meshes/link_1.STL" />
      </geometry>
      <material
        name="">
        <color
          rgba="0.792156862745098 0.819607843137255 0.933333333333333 1" />
      </material>
    </visual>
    <collision>
      <origin
        xyz="0 0 0"
        rpy="0 0 0" />
      <geometry>
        <mesh
          filename="package://robot_arm_description/meshes/link_1.STL" />
      </geometry>
    </collision>
  </link>
  <joint
    name="joint_1"
    type="continuous">
    <origin
      xyz="0 0 0.05"
      rpy="0 0 0" />
    <parent
      link="base_link" />
    <child
      link="link_1" />
    <axis
      xyz="0 0 1" />
  </joint>
  <link
    name="link_2">
    <inertial>
      <origin
        xyz="0.0249750944156842 0.0249772859698909 0.0468961083176771"
        rpy="0 0 0" />
      <mass
        value="0.064396141841368" />
      <inertia
        ixx="9.61544573728887E-05"
        ixy="-1.96129401588288E-05"
        ixz="-2.93770475865757E-05"
        iyy="8.73371118665447E-05"
        iyz="-3.67498044712087E-05"
        izz="4.4507328864253E-05" />
    </inertial>
    <visual>
      <origin
        xyz="0 0 0"
        rpy="0 0 0" />
      <geometry>
        <mesh
          filename="package://robot_arm_description/meshes/link_2.STL" />
      </geometry>
      <material
        name="">
        <color
          rgba="0 0.254901960784314 0.92156862745098 1" />
      </material>
    </visual>
    <collision>
      <origin
        xyz="0 0 0"
        rpy="0 0 0" />
      <geometry>
        <mesh
          filename="package://robot_arm_description/meshes/link_2.STL" />
      </geometry>
    </collision>
  </link>
  <joint
    name="joint_2"
    type="continuous">
    <origin
      xyz="0.00873499271692548 0.0108362687265375 0.040276480175933"
      rpy="0 0 0" />
    <parent
      link="link_1" />
    <child
      link="link_2" />
    <axis
      xyz="0.778551124052 -0.627581187765668 0" />
  </joint>
  <link
    name="link_3">
    <inertial>
      <origin
        xyz="0.0128052472574296 0.0340647193385334 0.0186847213480272"
        rpy="0 0 0" />
      <mass
        value="0.0502681192798898" />
      <inertia
        ixx="4.32011391528895E-05"
        ixy="-1.87968422837148E-05"
        ixz="-1.18045403059582E-05"
        iyy="3.45165558874064E-05"
        iyz="-1.48619379367344E-05"
        izz="4.43190576137703E-05" />
    </inertial>
    <visual>
      <origin
        xyz="0 0 0"
        rpy="0 0 0" />
      <geometry>
        <mesh
          filename="package://robot_arm_description/meshes/link_3.STL" />
      </geometry>
      <material
        name="">
        <color
          rgba="0.792156862745098 0.819607843137255 0.933333333333333 1" />
      </material>
    </visual>
    <collision>
      <origin
        xyz="0 0 0"
        rpy="0 0 0" />
      <geometry>
        <mesh
          filename="package://robot_arm_description/meshes/link_3.STL" />
      </geometry>
    </collision>
  </link>
  <joint
    name="joint_3"
    type="continuous">
    <origin
      xyz="0.0452765198294633 0.0561681677105227 0.0958914682762493"
      rpy="0 0 0" />
    <parent
      link="link_2" />
    <child
      link="link_3" />
    <axis
      xyz="-0.778551124051999 0.62758118776567 0" />
  </joint>
  <link
    name="link_4">
    <inertial>
      <origin
        xyz="-0.0117718696694758 -0.0224594299210791 -0.00731996582076389"
        rpy="0 0 0" />
      <mass
        value="0.016499491436809" />
      <inertia
        ixx="3.66487581324487E-06"
        ixy="-1.13581818040864E-06"
        ixz="-5.12400994022922E-07"
        iyy="4.28053026614363E-06"
        iyz="-3.05400205956593E-07"
        izz="3.60163959371384E-06" />
    </inertial>
    <visual>
      <origin
        xyz="0 0 0"
        rpy="0 0 0" />
      <geometry>
        <mesh
          filename="package://robot_arm_description/meshes/link_4.STL" />
      </geometry>
      <material
        name="">
        <color
          rgba="0.792156862745098 0.819607843137255 0.933333333333333 1" />
      </material>
    </visual>
    <collision>
      <origin
        xyz="0 0 0"
        rpy="0 0 0" />
      <geometry>
        <mesh
          filename="package://robot_arm_description/meshes/link_4.STL" />
      </geometry>
    </collision>
  </link>
  <joint
    name="joint_4"
    type="continuous">
    <origin
      xyz="0.066053819111936 0.100267943565289 0.0584895163370014"
      rpy="0 0 0" />
    <parent
      link="link_3" />
    <child
      link="link_4" />
    <axis
      xyz="0.552264856359974 0.685116815282897 0.474993134525457" />
  </joint>
  <link
    name="link_5">
    <inertial>
      <origin
        xyz="-0.0512259253993248 -0.0600862766687876 -0.00480330153133091"
        rpy="0 0 0" />
      <mass
        value="0.0122628916627226" />
      <inertia
        ixx="3.02510506493144E-06"
        ixy="-1.78877095938349E-06"
        ixz="-4.78051886241324E-07"
        iyy="2.40088202838795E-06"
        iyz="-6.05353933747182E-07"
        izz="3.9470456236568E-06" />
    </inertial>
    <visual>
      <origin
        xyz="0 0 0"
        rpy="0 0 0" />
      <geometry>
        <mesh
          filename="package://robot_arm_description/meshes/link_5.STL" />
      </geometry>
      <material
        name="">
        <color
          rgba="0.792156862745098 0.819607843137255 0.933333333333333 1" />
      </material>
    </visual>
    <collision>
      <origin
        xyz="0 0 0"
        rpy="0 0 0" />
      <geometry>
        <mesh
          filename="package://robot_arm_description/meshes/link_5.STL" />
      </geometry>
    </collision>
  </link>
  <joint
    name="joint_5"
    type="continuous">
    <origin
      xyz="0.0658770416469138 0.0497166404170352 0.006958042593945"
      rpy="0 0 0" />
    <parent
      link="link_4" />
    <child
      link="link_5" />
    <axis
      xyz="-0.759313420493717 0.650673886413552 0.00816229119891543" />
  </joint>
  <link
    name="link_6">
    <inertial>
      <origin
        xyz="-0.0101934963348007 -0.0117464957039731 0.00033075177043812"
        rpy="0 0 0" />
      <mass
        value="0.00291124967087628" />
      <inertia
        ixx="6.19055743826587E-07"
        ixy="-4.62957237829888E-07"
        ixz="-6.95310132008666E-10"
        iyy="4.82892780554864E-07"
        iyz="1.26580186551905E-08"
        izz="1.05766876849935E-06" />
    </inertial>
    <visual>
      <origin
        xyz="0 0 0"
        rpy="0 0 0" />
      <geometry>
        <mesh
          filename="package://robot_arm_description/meshes/link_6.STL" />
      </geometry>
      <material
        name="">
        <color
          rgba="0.792156862745098 0.819607843137255 0.933333333333333 1" />
      </material>
    </visual>
    <collision>
      <origin
        xyz="0 0 0"
        rpy="0 0 0" />
      <geometry>
        <mesh
          filename="package://robot_arm_description/meshes/link_6.STL" />
      </geometry>
    </collision>
  </link>
  <joint
    name="joint_6"
    type="continuous">
    <origin
      xyz="0 0 0"
      rpy="0 0 0" />
    <parent
      link="link_5" />
    <child
      link="link_6" />
    <axis
      xyz="0.65067 0.75931 0.0081623" />
  </joint>
  
  <!-- ros2_control configuration -->
  <ros2_control name="arm_controller" type="system">
    <hardware>
      <plugin>mock_components/GenericSystem</plugin>
    </hardware>
    <joint name="joint_1">
      <command_interface name="effort"/>
      <state_interface name="position"/>
      <state_interface name="velocity"/>
    </joint>
    <joint name="joint_2">
      <command_interface name="effort"/>
      <state_interface name="position"/>
      <state_interface name="velocity"/>
    </joint>
    <joint name="joint_3">
      <command_interface name="effort"/>
      <state_interface name="position"/>
      <state_interface name="velocity"/>
    </joint>
    <joint name="joint_4">
      <command_interface name="effort"/>
      <state_interface name="position"/>
      <state_interface name="velocity"/>
    </joint>
    <joint name="joint_5">
      <command_interface name="effort"/>
      <state_interface name="position"/>
      <state_interface name="velocity"/>
    </joint>
    <joint name="joint_6">
      <command_interface name="effort"/>
      <state_interface name="position"/>
      <state_interface name="velocity"/>
    </joint>
  </ros2_control>
</robot>